<robot name="tinybot">
  <link name="base_link">
    <inertial>
      <origin xyz="0.0079258 5.3524E-05 0.12812" rpy="1.57079632679 0 0" />
      <mass value="13.418" />
      <inertia ixx="0.13734" ixy="3.8873E-05" ixz="0.0035268" iyy="0.14138" iyz="0.00022692" izz="0.11173" />
    </inertial>
    <visual>
      <origin xyz="0 0 0" rpy="1.57079632679 0 0" />
      <geometry>
        <mesh filename="module_sets/tinybot/meshes/base_link_X10.STL" scale="0.001 0.001 0.001" />
      </geometry>
      <material name="">
        <color rgba="0.5 0.5 0.5 1" />
      </material>
    </visual>
    <collision>
      <origin xyz="0 0 0" rpy="1.57079632679 0 0" />
      <geometry>
        <mesh filename="module_sets/tinybot/meshes/base_link_X10.STL" scale="0.001 0.001 0.001" />
      </geometry>
    </collision>
  </link>
  <joint name="base_motor_joint" type="continuous">
    <origin xyz="0.0425 -0.0425 0.04" rpy="0 0 0" />
    <axis xyz="0 0 1" />
    <parent link="base_link" />
    <child link="base_motor_link" />
  </joint>
  <link name="base_motor_link">
    <inertial>
      <origin xyz="0.0 0 0.0" rpy="3.1415926535 0 0" />
      <mass value="13.418" />
      <inertia ixx="0.13734" ixy="3.8873E-05" ixz="0.0035268" iyy="0.14138" iyz="0.00022692" izz="0.11173" />
    </inertial>
    <visual>
      <origin xyz="0 0 0" rpy="3.1415926535 0 0" />
      <geometry>
        <mesh filename="module_sets/tinybot/meshes/RMD-X10-S2-V3.STL" scale="0.001 0.001 0.001" />
      </geometry>
      <material name="">
        <color rgba="0.5 0.5 0.5 1" />
      </material>
    </visual>
    <collision>
      <origin xyz="0 0 0" rpy="1.57079632679 0 0" />
      <geometry>
        <mesh filename="module_sets/tinybot/meshes/RMD-X10-S2-V3.STL" scale="0.001 0.001 0.001" />
      </geometry>
    </collision>
  </link>
</robot>